WARNING  urllib3.connectionpool:connectionpool.py:868 Retrying (Retry(total=2, connect=None, read=None, redirect=None, status=None)) after connection broken by 'NewConnectionError('<urllib3.connection.HTTPConnection object at 0x7f6d2cb365d0>: Failed to establish a new connection: [Errno 111] Connection refused')': /session/168b9d9e9660dd4bd518168245a9f034
WARNING  urllib3.connectionpool:connectionpool.py:868 Retrying (Retry(total=1, connect=None, read=None, redirect=None, status=None)) after connection broken by 'NewConnectionError('<urllib3.connection.HTTPConnection object at 0x7f6d2cb34170>: Failed to establish a new connection: [Errno 111] Connection refused')': /session/168b9d9e9660dd4bd518168245a9f034
WARNING  urllib3.connectionpool:connectionpool.py:868 Retrying (Retry(total=0, connect=None, read=None, redirect=None, status=None)) after connection broken by 'NewConnectionError('<urllib3.connection.HTTPConnection object at 0x7f6d2cb35490>: Failed to establish a new connection: [Errno 111] Connection refused')': /session/168b9d9e9660dd4bd518168245a9f034