{"name": "Проверка создания пользователя", "status": "broken", "statusDetails": {"message": "selenium.common.exceptions.WebDriverException: Message: Service /root/.wdm/drivers/chromedriver/linux64/114.0.5735.90/chromedriver unexpectedly exited. Status code was: 127", "trace": "@pytest.fixture\n    def browser():\n>       driver = webdriver.Chrome(service=Service(ChromeDriverManager().install()))\n\ntests/test_ui/conftest.py:11: \n_ _ _ _ _ _ _ _ _ _ _ _ _ _ _ _ _ _ _ _ _ _ _ _ _ _ _ _ _ _ _ _ _ _ _ _ _ _ _ _ \n/usr/local/lib/python3.12/site-packages/selenium/webdriver/chrome/webdriver.py:45: in __init__\n    super().__init__(\n/usr/local/lib/python3.12/site-packages/selenium/webdriver/chromium/webdriver.py:55: in __init__\n    self.service.start()\n/usr/local/lib/python3.12/site-packages/selenium/webdriver/common/service.py:113: in start\n    self.assert_process_still_running()\n_ _ _ _ _ _ _ _ _ _ _ _ _ _ _ _ _ _ _ _ _ _ _ _ _ _ _ _ _ _ _ _ _ _ _ _ _ _ _ _ \n\nself = <selenium.webdriver.chrome.service.Service object at 0x7f2552419520>\n\n    def assert_process_still_running(self) -> None:\n        \"\"\"Check if the underlying process is still running.\"\"\"\n        return_code = self.process.poll()\n        if return_code:\n>           raise WebDriverException(f\"Service {self._path} unexpectedly exited. Status code was: {return_code}\")\nE           selenium.common.exceptions.WebDriverException: Message: Service /root/.wdm/drivers/chromedriver/linux64/114.0.5735.90/chromedriver unexpectedly exited. Status code was: 127\n\n/usr/local/lib/python3.12/site-packages/selenium/webdriver/common/service.py:126: WebDriverException"}, "description": "\nЭтот тест проверяет:\n- Регистрацию пользователя с позитивным сценарием\n- Ввод рандомных значений с помощью библиотеки faker\n- Проверка успеха прохождения регистрации \nИЛИ\n- Проверка предупреждения, что пользователь уже создан с таким email\n", "attachments": [{"name": "stdout", "source": "1988f87e-0740-4255-a863-1bab0f5e106a-attachment.txt", "type": "text/plain"}], "start": 1760646027564, "stop": 1760646027564, "uuid": "0f54f0fd-55ef-4962-997b-b3242ce7bd9a", "historyId": "344dd844828b7875f5a780d9f1936342", "testCaseId": "344dd844828b7875f5a780d9f1936342", "fullName": "tests.test_ui.test_first#test_positive_registration_faker", "labels": [{"name": "tag", "value": "ui"}, {"name": "epic", "value": "Аутентификация и авторизация"}, {"name": "as_id", "value": "TEST-123"}, {"name": "owner", "value": "QA - evgeny_gord"}, {"name": "feature", "value": "Регистрация пользователей"}, {"name": "suite", "value": "Смоук тесты"}, {"name": "severity", "value": "critical"}, {"name": "tag", "value": "smoke"}, {"name": "parentSuite", "value": "tests.test_ui"}, {"name": "host", "value": "eeb215c29917"}, {"name": "thread", "value": "1-MainThread"}, {"name": "framework", "value": "pytest"}, {"name": "language", "value": "cpython3"}, {"name": "package", "value": "tests.test_ui.test_first"}], "links": [{"type": "tms", "url": "TC-789", "name": "https://testcase.com/TC-789"}, {"type": "issue", "url": "BUG-456", "name": "https://bugtracker.com/BUG-456"}, {"type": "link", "url": "https://jira.example.com/TEST-123", "name": "JIRA Task"}], "titlePath": ["tests", "test_ui", "test_first.py"]}