{"uuid": "06424221-0920-4c75-ad08-a9f9f1328358", "children": ["9a67514d-6ea8-4494-bba5-74e9cea03e47"], "befores": [{"name": "browser", "status": "broken", "statusDetails": {"message": "selenium.common.exceptions.SessionNotCreatedException: Message: session not created: probably user data directory is already in use, please specify a unique value for --user-data-dir argument, or don't use --user-data-dir; For documentation on this error, please visit: https://www.selenium.dev/documentation/webdriver/troubleshooting/errors#sessionnotcreatedexception\nStacktrace:\n#0 0x5564b585767a <unknown>\n#1 0x5564b52d6566 <unknown>\n#2 0x5564b5311b4c <unknown>\n#3 0x5564b530d7c4 <unknown>\n#4 0x5564b535cbd3 <unknown>\n#5 0x5564b535c286 <unknown>\n#6 0x5564b534e403 <unknown>\n#7 0x5564b531ab02 <unknown>\n#8 0x5564b531b7c1 <unknown>\n#9 0x5564b581b448 <unknown>\n#10 0x5564b581f2af <unknown>\n#11 0x5564b58028d9 <unknown>\n#12 0x5564b581fe55 <unknown>\n#13 0x5564b57e813f <unknown>\n#14 0x5564b58444b8 <unknown>\n#15 0x5564b5844693 <unknown>\n#16 0x5564b5856613 <unknown>\n#17 0x7f7b3a1c2b7b <unknown>\n\n", "trace": "  File \"/usr/local/lib/python3.12/site-packages/pluggy/_callers.py\", line 38, in run_old_style_hookwrapper\n    res = yield\n          ^^^^^\n  File \"/usr/local/lib/python3.12/site-packages/pluggy/_callers.py\", line 139, in _multicall\n    teardown.throw(exception)\n  File \"/usr/local/lib/python3.12/site-packages/_pytest/setuponly.py\", line 36, in pytest_fixture_setup\n    return (yield)\n            ^^^^^\n  File \"/usr/local/lib/python3.12/site-packages/pluggy/_callers.py\", line 121, in _multicall\n    res = hook_impl.function(*args)\n          ^^^^^^^^^^^^^^^^^^^^^^^^^\n  File \"/usr/local/lib/python3.12/site-packages/_pytest/fixtures.py\", line 1196, in pytest_fixture_setup\n    result = call_fixture_func(fixturefunc, request, kwargs)\n             ^^^^^^^^^^^^^^^^^^^^^^^^^^^^^^^^^^^^^^^^^^^^^^^\n  File \"/usr/local/lib/python3.12/site-packages/_pytest/fixtures.py\", line 923, in call_fixture_func\n    fixture_result = next(generator)\n                     ^^^^^^^^^^^^^^^\n  File \"/app/tests/test_ui/conftest.py\", line 11, in browser\n    driver = webdriver.Chrome(service=Service(ChromeDriverManager().install()))\n             ^^^^^^^^^^^^^^^^^^^^^^^^^^^^^^^^^^^^^^^^^^^^^^^^^^^^^^^^^^^^^^^^^^\n  File \"/usr/local/lib/python3.12/site-packages/selenium/webdriver/chrome/webdriver.py\", line 46, in __init__\n    super().__init__(\n  File \"/usr/local/lib/python3.12/site-packages/selenium/webdriver/chromium/webdriver.py\", line 71, in __init__\n    super().__init__(command_executor=executor, options=options)\n  File \"/usr/local/lib/python3.12/site-packages/selenium/webdriver/remote/webdriver.py\", line 263, in __init__\n    self.start_session(capabilities)\n  File \"/usr/local/lib/python3.12/site-packages/selenium/webdriver/remote/webdriver.py\", line 366, in start_session\n    response = self.execute(Command.NEW_SESSION, caps)[\"value\"]\n               ^^^^^^^^^^^^^^^^^^^^^^^^^^^^^^^^^^^^^^^\n  File \"/usr/local/lib/python3.12/site-packages/selenium/webdriver/remote/webdriver.py\", line 458, in execute\n    self.error_handler.check_response(response)\n  File \"/usr/local/lib/python3.12/site-packages/selenium/webdriver/remote/errorhandler.py\", line 232, in check_response\n    raise exception_class(message, screen, stacktrace)\n"}, "start": 1760647340551, "stop": 1760647341379}], "start": 1760647340551, "stop": 1760647341426}