{"uuid": "2e52a18e-d1ae-4dc7-b0ba-a66807132277", "children": ["0f255b41-259a-4611-8936-71804ce4a1b8"], "befores": [{"name": "browser", "status": "broken", "statusDetails": {"message": "selenium.common.exceptions.SessionNotCreatedException: Message: session not created: probably user data directory is already in use, please specify a unique value for --user-data-dir argument, or don't use --user-data-dir; For documentation on this error, please visit: https://www.selenium.dev/documentation/webdriver/troubleshooting/errors#sessionnotcreatedexception\nStacktrace:\n#0 0x55905a19667a <unknown>\n#1 0x559059c15566 <unknown>\n#2 0x559059c50b4c <unknown>\n#3 0x559059c4c7c4 <unknown>\n#4 0x559059c9bbd3 <unknown>\n#5 0x559059c9b286 <unknown>\n#6 0x559059c8d403 <unknown>\n#7 0x559059c59b02 <unknown>\n#8 0x559059c5a7c1 <unknown>\n#9 0x55905a15a448 <unknown>\n#10 0x55905a15e2af <unknown>\n#11 0x55905a1418d9 <unknown>\n#12 0x55905a15ee55 <unknown>\n#13 0x55905a12713f <unknown>\n#14 0x55905a1834b8 <unknown>\n#15 0x55905a183693 <unknown>\n#16 0x55905a195613 <unknown>\n#17 0x7f0131e49b7b <unknown>\n\n", "trace": "  File \"/usr/local/lib/python3.12/site-packages/pluggy/_callers.py\", line 38, in run_old_style_hookwrapper\n    res = yield\n          ^^^^^\n  File \"/usr/local/lib/python3.12/site-packages/pluggy/_callers.py\", line 139, in _multicall\n    teardown.throw(exception)\n  File \"/usr/local/lib/python3.12/site-packages/_pytest/setuponly.py\", line 36, in pytest_fixture_setup\n    return (yield)\n            ^^^^^\n  File \"/usr/local/lib/python3.12/site-packages/pluggy/_callers.py\", line 121, in _multicall\n    res = hook_impl.function(*args)\n          ^^^^^^^^^^^^^^^^^^^^^^^^^\n  File \"/usr/local/lib/python3.12/site-packages/_pytest/fixtures.py\", line 1196, in pytest_fixture_setup\n    result = call_fixture_func(fixturefunc, request, kwargs)\n             ^^^^^^^^^^^^^^^^^^^^^^^^^^^^^^^^^^^^^^^^^^^^^^^\n  File \"/usr/local/lib/python3.12/site-packages/_pytest/fixtures.py\", line 923, in call_fixture_func\n    fixture_result = next(generator)\n                     ^^^^^^^^^^^^^^^\n  File \"/app/tests/test_ui/conftest.py\", line 11, in browser\n    driver = webdriver.Chrome(service=Service(ChromeDriverManager().install()))\n             ^^^^^^^^^^^^^^^^^^^^^^^^^^^^^^^^^^^^^^^^^^^^^^^^^^^^^^^^^^^^^^^^^^\n  File \"/usr/local/lib/python3.12/site-packages/selenium/webdriver/chrome/webdriver.py\", line 46, in __init__\n    super().__init__(\n  File \"/usr/local/lib/python3.12/site-packages/selenium/webdriver/chromium/webdriver.py\", line 71, in __init__\n    super().__init__(command_executor=executor, options=options)\n  File \"/usr/local/lib/python3.12/site-packages/selenium/webdriver/remote/webdriver.py\", line 263, in __init__\n    self.start_session(capabilities)\n  File \"/usr/local/lib/python3.12/site-packages/selenium/webdriver/remote/webdriver.py\", line 366, in start_session\n    response = self.execute(Command.NEW_SESSION, caps)[\"value\"]\n               ^^^^^^^^^^^^^^^^^^^^^^^^^^^^^^^^^^^^^^^\n  File \"/usr/local/lib/python3.12/site-packages/selenium/webdriver/remote/webdriver.py\", line 458, in execute\n    self.error_handler.check_response(response)\n  File \"/usr/local/lib/python3.12/site-packages/selenium/webdriver/remote/errorhandler.py\", line 232, in check_response\n    raise exception_class(message, screen, stacktrace)\n"}, "start": 1760647337533, "stop": 1760647338790}], "start": 1760647337533, "stop": 1760647338841}