{"uuid": "720c625c-86db-4102-9ed8-6581da5eeda6", "children": ["84a8bfc1-0c36-4bf4-911b-787648e07ebe"], "befores": [{"name": "browser", "status": "broken", "statusDetails": {"message": "selenium.common.exceptions.SessionNotCreatedException: Message: session not created: probably user data directory is already in use, please specify a unique value for --user-data-dir argument, or don't use --user-data-dir; For documentation on this error, please visit: https://www.selenium.dev/documentation/webdriver/troubleshooting/errors#sessionnotcreatedexception\nStacktrace:\n#0 0x55aec38d167a <unknown>\n#1 0x55aec3350566 <unknown>\n#2 0x55aec338bb4c <unknown>\n#3 0x55aec33877c4 <unknown>\n#4 0x55aec33d6bd3 <unknown>\n#5 0x55aec33d6286 <unknown>\n#6 0x55aec33c8403 <unknown>\n#7 0x55aec3394b02 <unknown>\n#8 0x55aec33957c1 <unknown>\n#9 0x55aec3895448 <unknown>\n#10 0x55aec38992af <unknown>\n#11 0x55aec387c8d9 <unknown>\n#12 0x55aec3899e55 <unknown>\n#13 0x55aec386213f <unknown>\n#14 0x55aec38be4b8 <unknown>\n#15 0x55aec38be693 <unknown>\n#16 0x55aec38d0613 <unknown>\n#17 0x7f4e1ba5fb7b <unknown>\n\n", "trace": "  File \"/usr/local/lib/python3.12/site-packages/pluggy/_callers.py\", line 38, in run_old_style_hookwrapper\n    res = yield\n          ^^^^^\n  File \"/usr/local/lib/python3.12/site-packages/pluggy/_callers.py\", line 139, in _multicall\n    teardown.throw(exception)\n  File \"/usr/local/lib/python3.12/site-packages/_pytest/setuponly.py\", line 36, in pytest_fixture_setup\n    return (yield)\n            ^^^^^\n  File \"/usr/local/lib/python3.12/site-packages/pluggy/_callers.py\", line 121, in _multicall\n    res = hook_impl.function(*args)\n          ^^^^^^^^^^^^^^^^^^^^^^^^^\n  File \"/usr/local/lib/python3.12/site-packages/_pytest/fixtures.py\", line 1196, in pytest_fixture_setup\n    result = call_fixture_func(fixturefunc, request, kwargs)\n             ^^^^^^^^^^^^^^^^^^^^^^^^^^^^^^^^^^^^^^^^^^^^^^^\n  File \"/usr/local/lib/python3.12/site-packages/_pytest/fixtures.py\", line 923, in call_fixture_func\n    fixture_result = next(generator)\n                     ^^^^^^^^^^^^^^^\n  File \"/app/tests/test_ui/conftest.py\", line 11, in browser\n    driver = webdriver.Chrome(service=Service(ChromeDriverManager().install()))\n             ^^^^^^^^^^^^^^^^^^^^^^^^^^^^^^^^^^^^^^^^^^^^^^^^^^^^^^^^^^^^^^^^^^\n  File \"/usr/local/lib/python3.12/site-packages/selenium/webdriver/chrome/webdriver.py\", line 46, in __init__\n    super().__init__(\n  File \"/usr/local/lib/python3.12/site-packages/selenium/webdriver/chromium/webdriver.py\", line 71, in __init__\n    super().__init__(command_executor=executor, options=options)\n  File \"/usr/local/lib/python3.12/site-packages/selenium/webdriver/remote/webdriver.py\", line 263, in __init__\n    self.start_session(capabilities)\n  File \"/usr/local/lib/python3.12/site-packages/selenium/webdriver/remote/webdriver.py\", line 366, in start_session\n    response = self.execute(Command.NEW_SESSION, caps)[\"value\"]\n               ^^^^^^^^^^^^^^^^^^^^^^^^^^^^^^^^^^^^^^^\n  File \"/usr/local/lib/python3.12/site-packages/selenium/webdriver/remote/webdriver.py\", line 458, in execute\n    self.error_handler.check_response(response)\n  File \"/usr/local/lib/python3.12/site-packages/selenium/webdriver/remote/errorhandler.py\", line 232, in check_response\n    raise exception_class(message, screen, stacktrace)\n"}, "start": 1760647338852, "stop": 1760647339679}], "start": 1760647338852, "stop": 1760647339725}