{"uid":"9361bf693f19959d","name":"Проверка создания пользователя","fullName":"tests.test_ui.test_first#test_positive_registration_with_fixture_params","historyId":"56a131b505deecd572da5676d449fa86","time":{"start":1760646042124,"stop":1760646042124,"duration":0},"description":"\nЭтот тест проверяет:\n- Регистрацию пользователя с позитивным сценарием\n- Прохождение регистрации на данных параметров фикстуры registration_data_with_params (хранится в test_ui/conftest.py)\n- Проверка успеха прохождения регистрации \nИЛИ\n- Проверка предупреждения, что пользователь уже создан с таким email\n","descriptionHtml":"<p>Этот тест проверяет:</p>\n<ul>\n<li>Регистрацию пользователя с позитивным сценарием</li>\n<li>Прохождение регистрации на данных параметров фикстуры registration_data_with_params (хранится в test_ui/conftest.py)</li>\n<li>Проверка успеха прохождения регистрации<br />\nИЛИ</li>\n<li>Проверка предупреждения, что пользователь уже создан с таким email</li>\n</ul>\n","status":"broken","statusMessage":"selenium.common.exceptions.WebDriverException: Message: Service /root/.wdm/drivers/chromedriver/linux64/114.0.5735.90/chromedriver unexpectedly exited. Status code was: 127","statusTrace":"@pytest.fixture\n    def browser():\n>       driver = webdriver.Chrome(service=Service(ChromeDriverManager().install()))\n\ntests/test_ui/conftest.py:11: \n_ _ _ _ _ _ _ _ _ _ _ _ _ _ _ _ _ _ _ _ _ _ _ _ _ _ _ _ _ _ _ _ _ _ _ _ _ _ _ _ \n/usr/local/lib/python3.12/site-packages/selenium/webdriver/chrome/webdriver.py:45: in __init__\n    super().__init__(\n/usr/local/lib/python3.12/site-packages/selenium/webdriver/chromium/webdriver.py:55: in __init__\n    self.service.start()\n/usr/local/lib/python3.12/site-packages/selenium/webdriver/common/service.py:113: in start\n    self.assert_process_still_running()\n_ _ _ _ _ _ _ _ _ _ _ _ _ _ _ _ _ _ _ _ _ _ _ _ _ _ _ _ _ _ _ _ _ _ _ _ _ _ _ _ \n\nself = <selenium.webdriver.chrome.service.Service object at 0x7f255241dac0>\n\n    def assert_process_still_running(self) -> None:\n        \"\"\"Check if the underlying process is still running.\"\"\"\n        return_code = self.process.poll()\n        if return_code:\n>           raise WebDriverException(f\"Service {self._path} unexpectedly exited. Status code was: {return_code}\")\nE           selenium.common.exceptions.WebDriverException: Message: Service /root/.wdm/drivers/chromedriver/linux64/114.0.5735.90/chromedriver unexpectedly exited. Status code was: 127\n\n/usr/local/lib/python3.12/site-packages/selenium/webdriver/common/service.py:126: WebDriverException","flaky":false,"newFailed":false,"newBroken":false,"newPassed":false,"retriesCount":0,"retriesStatusChange":false,"beforeStages":[{"name":"_session_faker","time":{"start":1760646019678,"stop":1760646019819,"duration":141},"status":"passed","steps":[],"attachments":[],"parameters":[],"hasContent":false,"attachmentStep":false,"stepsCount":0,"shouldDisplayMessage":false,"attachmentsCount":0},{"name":"browser","time":{"start":1760646042127,"stop":1760646046854,"duration":4727},"status":"broken","statusMessage":"selenium.common.exceptions.WebDriverException: Message: Service /root/.wdm/drivers/chromedriver/linux64/114.0.5735.90/chromedriver unexpectedly exited. Status code was: 127\n\n","statusTrace":"  File \"/usr/local/lib/python3.12/site-packages/pluggy/_callers.py\", line 38, in run_old_style_hookwrapper\n    res = yield\n          ^^^^^\n  File \"/usr/local/lib/python3.12/site-packages/pluggy/_callers.py\", line 139, in _multicall\n    teardown.throw(exception)\n  File \"/usr/local/lib/python3.12/site-packages/pluggy/_callers.py\", line 53, in run_old_style_hookwrapper\n    return result.get_result()\n           ^^^^^^^^^^^^^^^^^^^\n  File \"/usr/local/lib/python3.12/site-packages/pluggy/_result.py\", line 103, in get_result\n    raise exc.with_traceback(tb)\n  File \"/usr/local/lib/python3.12/site-packages/pluggy/_callers.py\", line 38, in run_old_style_hookwrapper\n    res = yield\n          ^^^^^\n  File \"/usr/local/lib/python3.12/site-packages/pluggy/_callers.py\", line 121, in _multicall\n    res = hook_impl.function(*args)\n          ^^^^^^^^^^^^^^^^^^^^^^^^^\n  File \"/usr/local/lib/python3.12/site-packages/_pytest/fixtures.py\", line 1122, in pytest_fixture_setup\n    result = call_fixture_func(fixturefunc, request, kwargs)\n             ^^^^^^^^^^^^^^^^^^^^^^^^^^^^^^^^^^^^^^^^^^^^^^^\n  File \"/usr/local/lib/python3.12/site-packages/_pytest/fixtures.py\", line 917, in call_fixture_func\n    fixture_result = next(generator)\n                     ^^^^^^^^^^^^^^^\n  File \"/app/tests/test_ui/conftest.py\", line 11, in browser\n    driver = webdriver.Chrome(service=Service(ChromeDriverManager().install()))\n             ^^^^^^^^^^^^^^^^^^^^^^^^^^^^^^^^^^^^^^^^^^^^^^^^^^^^^^^^^^^^^^^^^^\n  File \"/usr/local/lib/python3.12/site-packages/selenium/webdriver/chrome/webdriver.py\", line 45, in __init__\n    super().__init__(\n  File \"/usr/local/lib/python3.12/site-packages/selenium/webdriver/chromium/webdriver.py\", line 55, in __init__\n    self.service.start()\n  File \"/usr/local/lib/python3.12/site-packages/selenium/webdriver/common/service.py\", line 113, in start\n    self.assert_process_still_running()\n  File \"/usr/local/lib/python3.12/site-packages/selenium/webdriver/common/service.py\", line 126, in assert_process_still_running\n    raise WebDriverException(f\"Service {self._path} unexpectedly exited. Status code was: {return_code}\")\n","steps":[],"attachments":[],"parameters":[],"hasContent":true,"attachmentStep":false,"stepsCount":0,"shouldDisplayMessage":true,"attachmentsCount":0}],"testStage":{"description":"\nЭтот тест проверяет:\n- Регистрацию пользователя с позитивным сценарием\n- Прохождение регистрации на данных параметров фикстуры registration_data_with_params (хранится в test_ui/conftest.py)\n- Проверка успеха прохождения регистрации \nИЛИ\n- Проверка предупреждения, что пользователь уже создан с таким email\n","status":"broken","statusMessage":"selenium.common.exceptions.WebDriverException: Message: Service /root/.wdm/drivers/chromedriver/linux64/114.0.5735.90/chromedriver unexpectedly exited. Status code was: 127","statusTrace":"@pytest.fixture\n    def browser():\n>       driver = webdriver.Chrome(service=Service(ChromeDriverManager().install()))\n\ntests/test_ui/conftest.py:11: \n_ _ _ _ _ _ _ _ _ _ _ _ _ _ _ _ _ _ _ _ _ _ _ _ _ _ _ _ _ _ _ _ _ _ _ _ _ _ _ _ \n/usr/local/lib/python3.12/site-packages/selenium/webdriver/chrome/webdriver.py:45: in __init__\n    super().__init__(\n/usr/local/lib/python3.12/site-packages/selenium/webdriver/chromium/webdriver.py:55: in __init__\n    self.service.start()\n/usr/local/lib/python3.12/site-packages/selenium/webdriver/common/service.py:113: in start\n    self.assert_process_still_running()\n_ _ _ _ _ _ _ _ _ _ _ _ _ _ _ _ _ _ _ _ _ _ _ _ _ _ _ _ _ _ _ _ _ _ _ _ _ _ _ _ \n\nself = <selenium.webdriver.chrome.service.Service object at 0x7f255241dac0>\n\n    def assert_process_still_running(self) -> None:\n        \"\"\"Check if the underlying process is still running.\"\"\"\n        return_code = self.process.poll()\n        if return_code:\n>           raise WebDriverException(f\"Service {self._path} unexpectedly exited. Status code was: {return_code}\")\nE           selenium.common.exceptions.WebDriverException: Message: Service /root/.wdm/drivers/chromedriver/linux64/114.0.5735.90/chromedriver unexpectedly exited. Status code was: 127\n\n/usr/local/lib/python3.12/site-packages/selenium/webdriver/common/service.py:126: WebDriverException","steps":[],"attachments":[{"uid":"b32cd293f570ff5","name":"stdout","source":"b32cd293f570ff5.txt","type":"text/plain","size":137}],"parameters":[],"hasContent":true,"attachmentStep":false,"stepsCount":0,"shouldDisplayMessage":true,"attachmentsCount":1},"afterStages":[],"labels":[{"name":"tag","value":"ui"},{"name":"epic","value":"Аутентификация и авторизация"},{"name":"as_id","value":"TEST-123"},{"name":"owner","value":"QA - evgeny_gord"},{"name":"feature","value":"Регистрация пользователей"},{"name":"suite","value":"Смоук тесты"},{"name":"severity","value":"critical"},{"name":"tag","value":"smoke"},{"name":"parentSuite","value":"tests.test_ui"},{"name":"host","value":"eeb215c29917"},{"name":"thread","value":"1-MainThread"},{"name":"framework","value":"pytest"},{"name":"language","value":"cpython3"},{"name":"package","value":"tests.test_ui.test_first"},{"name":"resultFormat","value":"allure2"}],"parameters":[{"name":"registration_data_with_params","value":"{'email': 'test4@mail.ru', 'name': 'User27', 'password': 'qwertyu3'}"}],"links":[{"name":"https://testcase.com/TC-789","url":"TC-789","type":"tms"},{"name":"https://bugtracker.com/BUG-456","url":"BUG-456","type":"issue"},{"name":"JIRA Task","url":"https://jira.example.com/TEST-123","type":"link"}],"hidden":true,"retry":true,"extra":{"categories":[],"tags":["ui","smoke"]},"source":"9361bf693f19959d.json","parameterValues":["{'email': 'test4@mail.ru', 'name': 'User27', 'password': 'qwertyu3'}"]}